Workbook
Name SegmentaçãodeDados_Department: #N/A
Name SegmentaçãodeDados_Gender: #N/A
Name SegmentaçãodeDados_State: #N/A

Sheet HumanResource
A1: Employee_ID,First Name,Last Name,Gender,State,City,Education Level,Birthdate,Hiredate,Termdate,Department,Job Title,Salary,Performance Rating
A2: 00-95822412,Danielle,Johnson,Female,New York,New York City,High School,13/02/1980,16/04/2016,5/7/2021,Customer Service,Help Desk Technician,81552,Needs Improvement
A3: 00-42868828,John,Taylor,Male,North Carolina,Charlotte,Bachelor,22/09/1987,9/2/2017,14/06/2019,IT,System Administrator,107520,Good
A4: 00-83197857,Erica,Mcclain,Male,New York,New York City,Bachelor,19/05/1994,3/2/2016,6/3/2021,Operations,Logistics Coordinator,61104,Good
A5: 00-13999315,Brittany,Johnson,Male,New York,New York City,Bachelor,18/04/1980,6/2/2016,6/11/2018,Operations,Inventory Specialist,73770,Good
A6: 00-90801586,Jeffery,Wagner,Female,New York,New York City,Bachelor,7/4/1985,11/1/2015,,Operations,Operations Analyst,55581,Satisfactory
A7: 00-97226012,Anna,Baldwin,Female,New York,New York City,Bachelor,31/05/1988,30/09/2022,29/03/2023,Operations,Operations Analyst,73800,Good
A8: 00-70291817,Amy,Robinson,Male,New York,New York City,Bachelor,16/07/1991,16/08/2020,12/2/2021,Finance,Accountant,68181,Good
A9: 00-31429110,Joshua,Booth,Female,New York,New York City,Bachelor,19/09/1995,22/10/2022,20/04/2023,Finance,Accounts Payable Specialist,54499,Good
A10: 00-30868105,Linda,Wolfe,Male,New York,New York City,High School,11/5/2002,13/05/2017,15/11/2021,Operations,Inventory Specialist,57340,Needs Improvement
A11: 00-22448136,Joshua,Lewis,Female,New York,New York City,Bachelor,21/11/1980,24/10/2018,30/03/2022,Operations,Logistics Coordinator,54065,Good
A12: 00-56164955,Matthew,Davis,Female,New York,New York City,High School,8/2/1994,7/2/2021,6/8/2021,Marketing,SEO Specialist,83262,Needs Improvement
... A8951: 00-50413766,Derek,Thornton,Female,New York,Rochester,PhD,4/8/1993,15/08/2017,,Sales,Sales Specialist,68351,Good

Sheet ADEQUAÇÃO
A1: Employee_ID | B1: First Name | C1: Last Name | D1: Gender | E1: State | F1: City | G1: Education Level | H1: Birthdate | I1: Hiredate | J1: Termdate | K1: Department | L1: Job Title | M1: Salary | N1: Performance Rating | O1: Tenure | P1: Turnover | Q1: Performance Score
A2: 00-95822412 | B2: Danielle | C2: Johnson | D2: Female | E2: New York | F2: New York City | G2: High School | H2: 29264 | I2: 42476 | J2: 44382 | K2: Customer Service | L2: Help Desk Technician | M2: 81552 | N2: Needs Improvement | O2: 9.9835616 | P2: =IF(J2<>"","DESLIGADO","ATIVO") -> DESLIGADO | Q2: =IF(N2="Excellent",5,IF(N2="Good",4,IF(N2="Satisfactory",3,0))) -> 0
A3: 00-42868828 | B3: John | C3: Taylor | D3: Male | E3: North Carolina | F3: Charlotte | G3: Bachelor | H3: 32042 | I3: 42775 | J3: 43630 | K3: IT | L3: System Administrator | M3: 107520 | N3: Good | O3: 9.1643836 | P3: =IF(J3<>"","DESLIGADO","ATIVO") -> DESLIGADO | Q3: =IF(N3="Excellent",5,IF(N3="Good",4,IF(N3="Satisfactory",3,0))) -> 4
A4: 00-83197857 | B4: Erica | C4: Mcclain | D4: Male | E4: New York | F4: New York City | G4: Bachelor | H4: 34473 | I4: 42403 | J4: 44261 | K4: Operations | L4: Logistics Coordinator | M4: 61104 | N4: Good | O4: 10.183562 | P4: =IF(J4<>"","DESLIGADO","ATIVO") -> DESLIGADO | Q4: =IF(N4="Excellent",5,IF(N4="Good",4,IF(N4="Satisfactory",3,0))) -> 4
A5: 00-13999315 | B5: Brittany | C5: Johnson | D5: Male | E5: New York | F5: New York City | G5: Bachelor | H5: 29329 | I5: 42406 | J5: 43410 | K5: Operations | L5: Inventory Specialist | M5: 73770 | N5: Good | O5: 10.175342 | P5: =IF(J5<>"","DESLIGADO","ATIVO") -> DESLIGADO | Q5: =IF(N5="Excellent",5,IF(N5="Good",4,IF(N5="Satisfactory",3,0))) -> 4
A6: 00-90801586 | B6: Jeffery | C6: Wagner | D6: Female | E6: New York | F6: New York City | G6: Bachelor | H6: 31144 | I6: 42015 | K6: Operations | L6: Operations Analyst | M6: 55581 | N6: Satisfactory | O6: 11.246575 | P6: =IF(J6<>"","DESLIGADO","ATIVO") -> ATIVO | Q6: =IF(N6="Excellent",5,IF(N6="Good",4,IF(N6="Satisfactory",3,0))) -> 3
A7: 00-97226012 | B7: Anna | C7: Baldwin | D7: Female | E7: New York | F7: New York City | G7: Bachelor | H7: 32294 | I7: 44834 | J7: 45014 | K7: Operations | L7: Operations Analyst | M7: 73800 | N7: Good | O7: 3.5232877 | P7: =IF(J7<>"","DESLIGADO","ATIVO") -> DESLIGADO | Q7: =IF(N7="Excellent",5,IF(N7="Good",4,IF(N7="Satisfactory",3,0))) -> 4
A8: 00-70291817 | B8: Amy | C8: Robinson | D8: Male | E8: New York | F8: New York City | G8: Bachelor | H8: 33435 | I8: 44059 | J8: 44239 | K8: Finance | L8: Accountant | M8: 68181 | N8: Good | O8: 5.6465753 | P8: =IF(J8<>"","DESLIGADO","ATIVO") -> DESLIGADO | Q8: =IF(N8="Excellent",5,IF(N8="Good",4,IF(N8="Satisfactory",3,0))) -> 4
A9: 00-31429110 | B9: Joshua | C9: Booth | D9: Female | E9: New York | F9: New York City | G9: Bachelor | H9: 34961 | I9: 44856 | J9: 45036 | K9: Finance | L9: Accounts Payable Specialist | M9: 54499 | N9: Good | O9: 3.4630137 | P9: =IF(J9<>"","DESLIGADO","ATIVO") -> DESLIGADO | Q9: =IF(N9="Excellent",5,IF(N9="Good",4,IF(N9="Satisfactory",3,0))) -> 4
A10: 00-30868105 | B10: Linda | C10: Wolfe | D10: Male | E10: New York | F10: New York City | G10: High School | H10: 37387 | I10: 42868 | J10: 44515 | K10: Operations | L10: Inventory Specialist | M10: 57340 | N10: Needs Improvement | O10: 8.909589 | P10: =IF(J10<>"","DESLIGADO","ATIVO") -> DESLIGADO | Q10: =IF(N10="Excellent",5,IF(N10="Good",4,IF(N10="Satisfactory",3,0))) -> 0
A11: 00-22448136 | B11: Joshua | C11: Lewis | D11: Female | E11: New York | F11: New York City | G11: Bachelor | H11: 29546 | I11: 43397 | J11: 44650 | K11: Operations | L11: Logistics Coordinator | M11: 54065 | N11: Good | O11: 7.460274 | P11: =IF(J11<>"","DESLIGADO","ATIVO") -> DESLIGADO | Q11: =IF(N11="Excellent",5,IF(N11="Good",4,IF(N11="Satisfactory",3,0))) -> 4
A12: 00-56164955 | B12: Matthew | C12: Davis | D12: Female | E12: New York | F12: New York City | G12: High School | H12: 34373 | I12: 44234 | J12: 44414 | K12: Marketing | L12: SEO Specialist | M12: 83262 | N12: Needs Improvement | O12: 5.1671233 | P12: =IF(J12<>"","DESLIGADO","ATIVO") -> DESLIGADO | Q12: =IF(N12="Excellent",5,IF(N12="Good",4,IF(N12="Satisfactory",3,0))) -> 0
A13: 00-71662963 | B13: Michael | C13: Cooper | D13: Female | E13: New York | F13: New York City | G13: High School | H13: 27145 | I13: 43933 | J13: 45319 | K13: HR | L13: Recruiter | M13: 61651 | N13: Needs Improvement | O13: 5.9917808 | P13: =IF(J13<>"","DESLIGADO","ATIVO") -> DESLIGADO | Q13: =IF(N13="Excellent",5,IF(N13="Good",4,IF(N13="Satisfactory",3,0))) -> 0
A14: 00-84093639 | B14: Lindsay | C14: Blair | D14: Male | E14: New York | F14: New York City | G14: Bachelor | H14: 24618 | I14: 42944 | J14: 43124 | K14: Operations | L14: Operations Analyst | M14: 75509 | N14: Good | O14: 8.7013699 | P14: =IF(J14<>"","DESLIGADO","ATIVO") -> DESLIGADO | Q14: =IF(N14="Excellent",5,IF(N14="Good",4,IF(N14="Satisfactory",3,0))) -> 4
A15: 00-58537831 | B15: David | C15: Nielsen | D15: Female | E15: New York | F15: New York City | G15: High School | H15: 37098 | I15: 43861 | J15: 44041 | K15: Customer Service | L15: Help Desk Technician | M15: 67011 | N15: Needs Improvement | O15: 6.1890411 | P15: =IF(J15<>"","DESLIGADO","ATIVO") -> DESLIGADO | Q15: =IF(N15="Excellent",5,IF(N15="Good",4,IF(N15="Satisfactory",3,0))) -> 0
A16: 00-16150444 | B16: Andrea | C16: Calderon | D16: Male | E16: Michigan | F16: Grand Rapids | G16: Bachelor | H16: 31919 | I16: 44802 | J16: 44982 | K16: IT | L16: IT Support Specialist | M16: 60136 | N16: Good | O16: 3.6109589 | P16: =IF(J16<>"","DESLIGADO","ATIVO") -> DESLIGADO | Q16: =IF(N16="Excellent",5,IF(N16="Good",4,IF(N16="Satisfactory",3,0))) -> 4
A17: 00-41244663 | B17: Nicole | C17: Ward | D17: Male | E17: New York | F17: New York City | G17: Bachelor | H17: 23358 | I17: 45001 | J17: 45181 | K17: Operations | L17: Logistics Coordinator | M17: 67552 | N17: Satisfactory | O17: 3.0657534 | P17: =IF(J17<>"","DESLIGADO","ATIVO") -> DESLIGADO | Q17: =IF(N17="Excellent",5,IF(N17="Good",4,IF(N17="Satisfactory",3,0))) -> 3
A18: 00-70855700 | B18: Janet | C18: Williams | D18: Male | E18: Michigan | F18: Grand Rapids | G18: Bachelor | H18: 37616 | I18: 44285 | J18: 44465 | K18: Operations | L18: Inventory Specialist | M18: 59934 | N18: Good | O18: 5.0273973 | P18: =IF(J18<>"","DESLIGADO","ATIVO") -> DESLIGADO | Q18: =IF(N18="Excellent",5,IF(N18="Good",4,IF(N18="Satisfactory",3,0))) -> 4
... A27: 00-97971488 | B27: Jeffrey | C27: Nguyen | D27: Male | E27: New York | F27: New York City | G27: Bachelor | H27: 33956 | I27: 44129 | J27: 44496 | K27: Operations | L27: Inventory Specialist | M27: 65830 | N27: Good | O27: 5.4547945 | P27: =IF(J27<>"","DESLIGADO","ATIVO") -> DESLIGADO | Q27: =IF(N27="Excellent",5,IF(N27="Good",4,IF(N27="Satisfactory",3,0))) -> 4
A28: 00-29175900 | B28: Kimberly | C28: Perez | D28: Male | E28: New York | F28: New York City | G28: Bachelor | H28: 25891 | I28: 42748 | K28: Marketing | L28: Content Creator | M28: 68419 | N28: Good | O28: 9.2383562 | P28: =IF(J28<>"","DESLIGADO","ATIVO") -> ATIVO | Q28: =IF(N28="Excellent",5,IF(N28="Good",4,IF(N28="Satisfactory",3,0))) -> 4
A29: 00-85345555 | B29: Linda | C29: Morales | D29: Male | E29: New York | F29: New York City | G29: Bachelor | H29: 34079 | I29: 43856 | J29: 44295 | K29: Sales | L29: Sales Specialist | M29: 71110 | N29: Needs Improvement | O29: 6.2027397 | P29: =IF(J29<>"","DESLIGADO","ATIVO") -> DESLIGADO | Q29: =IF(N29="Excellent",5,IF(N29="Good",4,IF(N29="Satisfactory",3,0))) -> 0
A30: 00-67503414 | B30: Jason | C30: Hahn | D30: Male | E30: Ohio | F30: Cleveland | G30: Bachelor | H30: 28515 | I30: 43076 | J30: 43255 | K30: IT | L30: System Administrator | M30: 84205 | N30: Excellent | O30: 8.339726 | P30: =IF(J30<>"","DESLIGADO","ATIVO") -> DESLIGADO | Q30: =IF(N30="Excellent",5,IF(N30="Good",4,IF(N30="Satisfactory",3,0))) -> 5
A31: 00-39436733 | B31: Jennifer | C31: Lewis | D31: Male | E31: New York | F31: New York City | G31: Master | H31: 30212 | I31: 43293 | J31: 43473 | K31: Sales | L31: Sales Specialist | M31: 67953 | N31: Good | O31: 7.7452055 | P31: =IF(J31<>"","DESLIGADO","ATIVO") -> DESLIGADO | Q31: =IF(N31="Excellent",5,IF(N31="Good",4,IF(N31="Satisfactory",3,0))) -> 4
A32: 00-76238574 | B32: Randall | C32: Rocha | D32: Male | E32: New York | F32: New York City | G32: High School | H32: 22184 | I32: 42548 | J32: 44326 | K32: IT | L32: IT Support Specialist | M32: 58445 | N32: Needs Improvement | O32: 9.7863014 | P32: =IF(J32<>"","DESLIGADO","ATIVO") -> DESLIGADO | Q32: =IF(N32="Excellent",5,IF(N32="Good",4,IF(N32="Satisfactory",3,0))) -> 0
A33: 00-24716857 | B33: Douglas | C33: Taylor | D33: Female | E33: New York | F33: New York City | G33: Bachelor | H33: 33802 | I33: 43025 | J33: 44516 | K33: Customer Service | L33: Customer Service Representative | M33: 58697 | N33: Satisfactory | O33: 8.4794521 | P33: =IF(J33<>"","DESLIGADO","ATIVO") -> DESLIGADO | Q33: =IF(N33="Excellent",5,IF(N33="Good",4,IF(N33="Satisfactory",3,0))) -> 3
A34: 00-66661351 | B34: Anna | C34: Baker | D34: Male | E34: New York | F34: New York City | G34: PhD | H34: 25700 | I34: 44058 | J34: 44882 | K34: Sales | L34: Sales Specialist | M34: 77156 | N34: Excellent | O34: 5.6493151 | P34: =IF(J34<>"","DESLIGADO","ATIVO") -> DESLIGADO | Q34: =IF(N34="Excellent",5,IF(N34="Good",4,IF(N34="Satisfactory",3,0))) -> 5
A35: 00-89978790 | B35: Ross | C35: Silva | D35: Female | E35: New York | F35: New York City | G35: Bachelor | H35: 37589 | I35: 45432 | J35: 45612 | K35: Sales | L35: Sales Specialist | M35: 81038 | N35: Excellent | O35: 1.8849315 | P35: =IF(J35<>"","DESLIGADO","ATIVO") -> DESLIGADO | Q35: =IF(N35="Excellent",5,IF(N35="Good",4,IF(N35="Satisfactory",3,0))) -> 5
A36: 00-84252722 | B36: Jeffrey | C36: Bright | D36: Male | E36: New York | F36: New York City | G36: Bachelor | H36: 29362 | I36: 42933 | J36: 43113 | K36: Finance | L36: Accounts Payable Specialist | M36: 71339 | N36: Satisfactory | O36: 8.7315068 | P36: =IF(J36<>"","DESLIGADO","ATIVO") -> DESLIGADO | Q36: =IF(N36="Excellent",5,IF(N36="Good",4,IF(N36="Satisfactory",3,0))) -> 3
A37: 00-25374874 | B37: Trevor | C37: Campos | D37: Male | E37: New York | F37: New York City | G37: Master | H37: 30366 | I37: 44896 | J37: 45076 | K37: Operations | L37: Operations Analyst | M37: 81316 | N37: Excellent | O37: 3.3534247 | P37: =IF(J37<>"","DESLIGADO","ATIVO") -> DESLIGADO | Q37: =IF(N37="Excellent",5,IF(N37="Good",4,IF(N37="Satisfactory",3,0))) -> 5
A38: 00-45812670 | B38: Daniel | C38: Burton | D38: Female | E38: New York | F38: New York City | G38: Bachelor | H38: 37065 | I38: 44869 | J38: 45336 | K38: IT | L38: Software Developer | M38: 96947 | N38: Excellent | O38: 3.4273973 | P38: =IF(J38<>"","DESLIGADO","ATIVO") -> DESLIGADO | Q38: =IF(N38="Excellent",5,IF(N38="Good",4,IF(N38="Satisfactory",3,0))) -> 5
A39: 00-49392920 | B39: Erin | C39: Carlson | D39: Male | E39: New York | F39: New York City | G39: Bachelor | H39: 30761 | I39: 43615 | J39: 44315 | K39: Operations | L39: Logistics Coordinator | M39: 67437 | N39: Excellent | O39: 6.8630137 | P39: =IF(J39<>"","DESLIGADO","ATIVO") -> DESLIGADO | Q39: =IF(N39="Excellent",5,IF(N39="Good",4,IF(N39="Satisfactory",3,0))) -> 5
A40: 00-45351479 | B40: Patrick | C40: Ferrell | D40: Female | E40: Michigan | F40: Detroit | G40: PhD | H40: 25343 | I40: 43305 | J40: 43485 | K40: Sales | L40: Sales Consultant | M40: 116328 | N40: Excellent | O40: 7.7123288 | P40: =IF(J40<>"","DESLIGADO","ATIVO") -> DESLIGADO | Q40: =IF(N40="Excellent",5,IF(N40="Good",4,IF(N40="Satisfactory",3,0))) -> 5
... A46: 00-51273847 | B46: Jennifer | C46: Stanton | D46: Male | E46: New York | F46: New York City | G46: Bachelor | H46: 21893 | I46: 43031 | J46: 43436 | K46: Customer Service | L46: Support Specialist | M46: 68635 | N46: Satisfactory | O46: 8.4630137 | P46: =IF(J46<>"","DESLIGADO","ATIVO") -> DESLIGADO | Q46: =IF(N46="Excellent",5,IF(N46="Good",4,IF(N46="Satisfactory",3,0))) -> 3
A47: 00-20570592 | B47: Guy | C47: Gaines | D47: Male | E47: New York | F47: New York City | G47: Bachelor | H47: 37544 | I47: 42708 | K47: Sales | L47: Sales Representative | M47: 80367 | N47: Satisfactory | O47: 9.3479452 | P47: =IF(J47<>"","DESLIGADO","ATIVO") -> ATIVO | Q47: =IF(N47="Excellent",5,IF(N47="Good",4,IF(N47="Satisfactory",3,0))) -> 3
A48: 00-19289546 | B48: Colleen | C48: Skinner | D48: Female | E48: New York | F48: New York City | G48: Bachelor | H48: 29921 | I48: 43297 | J48: 43477 | K48: Operations | L48: Inventory Specialist | M48: 63169 | N48: Good | O48: 7.7342466 | P48: =IF(J48<>"","DESLIGADO","ATIVO") -> DESLIGADO | Q48: =IF(N48="Excellent",5,IF(N48="Good",4,IF(N48="Satisfactory",3,0))) -> 4
A49: 00-26879290 | B49: Chelsea | C49: Hernandez | D49: Female | E49: Pennsylvania | F49: Philadelphia | G49: Master | H49: 30243 | I49: 42666 | J49: 43621 | K49: Sales | L49: Sales Consultant | M49: 71142 | N49: Good | O49: 9.4630137 | P49: =IF(J49<>"","DESLIGADO","ATIVO") -> DESLIGADO | Q49: =IF(N49="Excellent",5,IF(N49="Good",4,IF(N49="Satisfactory",3,0))) -> 4
A50: 00-32162965 | B50: Evan | C50: Ashley | D50: Male | E50: New York | F50: New York City | G50: High School | H50: 30575 | I50: 43094 | J50: 43441 | K50: Operations | L50: Inventory Specialist | M50: 58830 | N50: Needs Improvement | O50: 8.290411 | P50: =IF(J50<>"","DESLIGADO","ATIVO") -> DESLIGADO | Q50: =IF(N50="Excellent",5,IF(N50="Good",4,IF(N50="Satisfactory",3,0))) -> 0
A51: 00-38427073 | B51: Alyssa | C51: Smith | D51: Female | E51: Michigan | F51: Grand Rapids | G51: Bachelor | H51: 25682 | I51: 45417 | J51: 45597 | K51: Customer Service | L51: Customer Service Representative | M51: 66218 | N51: Satisfactory | O51: 1.9260274 | P51: =IF(J51<>"","DESLIGADO","ATIVO") -> DESLIGADO | Q51: =IF(N51="Excellent",5,IF(N51="Good",4,IF(N51="Satisfactory",3,0))) -> 3
A52: 00-36998038 | B52: Tracy | C52: Rodriguez | D52: Female | E52: New York | F52: New York City | G52: High School | H52: 29166 | I52: 44702 | J52: 44882 | K52: Marketing | L52: SEO Specialist | M52: 88887 | N52: Needs Improvement | O52: 3.8849315 | P52: =IF(J52<>"","DESLIGADO","ATIVO") -> DESLIGADO | Q52: =IF(N52="Excellent",5,IF(N52="Good",4,IF(N52="Satisfactory",3,0))) -> 0
A53: 00-97225156 | B53: Natasha | C53: Decker | D53: Male | E53: New York | F53: New York City | G53: PhD | H53: 21767 | I53: 43220 | J53: 45246 | K53: Sales | L53: Sales Consultant | M53: 72859 | N53: Excellent | O53: 7.9452055 | P53: =IF(J53<>"","DESLIGADO","ATIVO") -> DESLIGADO | Q53: =IF(N53="Excellent",5,IF(N53="Good",4,IF(N53="Satisfactory",3,0))) -> 5
...

Sheet ANÁLISE
A1: TOTAL COLABORADORES | B1: TOTAL DE DESLIGADOS | C1: TURNOVER | D1: MÉDIA DE DESEMPENHO | E1: TEMPO MÉDIO DE EMPRESA
A2: =COUNTA(Tabela1[[#This Row],[Employee_ID]]:'ADEQUAÇÃO'!A8951) -> 8950 | B2: =COUNTIF(Tabela1[[#This Row],[Termdate]]:'ADEQUAÇÃO'!J8951,"<>") -> 966 | C2: =COUNTIF(ADEQUAÇÃO!J2:J8951,"<>")/COUNTA(ADEQUAÇÃO!A2:A8951) -> 0.10793296 | D2: =AVERAGE(Tabela1[[#This Row],[Performance Score ]]:'ADEQUAÇÃO'!Q8951) -> 3.3939665 | E2: =AVERAGE(Tabela1[[#This Row],[Tenure]]:'ADEQUAÇÃO'!O8951)/365 -> 0.016814762
Q4: Rótulos de Linha | R4: Colaboradores por Departamento
Q5: Operations | R5: 2718
Q6: Sales | R6: 1835
Q7: Customer Service | R7: 1673
Q8: IT | R8: 1382
Q9: Marketing | R9: 718
Q10: Finance | R10: 452
Q11: HR | R11: 172
Q12: Total Geral | R12: 8950
Q15: Termdate | R15: (Vários itens)
Q17: Rótulos de Linha | R17: Turnover por Departamento
Q18: Operations | R18: 289
Q19: Sales | R19: 201
Q20: Customer Service | R20: 184
Q21: IT | R21: 139
Q22: Marketing | R22: 70
Q23: Finance | R23: 63
Q24: HR | R24: 20
Q25: Total Geral | R25: 966
Q31: Rótulos de Linha | R31: Desempenho Médio por Departamento
Q32: Sales | R32: 3.7100817
Q33: Finance | R33: 3.6128319
Q34: IT | R34: 3.4565847
Q35: Operations | R35: 3.3863135
Q36: HR | R36: 3.3837209
Q37: Marketing | R37: 3.1657382
Q38: Customer Service | R38: 3.0478183
Q39: Total Geral | R39: 3.3939665
Q45: Rótulos de Linha | R45: Tempo Médio de Empresa por Departamento
Q46: Sales | R46: 6.2173267
Q47: Finance | R47: 6.1745666
Q48: IT | R48: 6.1524176
Q49: Operations | R49: 6.1209522
Q50: Marketing | R50: 6.100248
Q51: Customer Service | R51: 6.0917079
Q52: HR | R52: 5.9251832
Q53: Total Geral | R53: 6.1373882

Sheet DASHBOARD
A1: Dashboard de RH | People Analytics
A2: TOTAL COLABORADORES | B2: TOTAL DE DESLIGADOS | C2: TURNOVER | D2: MÉDIA DE DESEMPENHO | E2: TEMPO MÉDIO DE EMPRESA
A3: =COUNTA(Tabela1[[#This Row],[Employee_ID]]:'ADEQUAÇÃO'!A8952) -> 8949 | B3: =COUNTIF(Tabela1[[#This Row],[Termdate]]:'ADEQUAÇÃO'!J8952,"<>") -> 965 | C3: =COUNTIF(ADEQUAÇÃO!J3:J8952,"<>")/COUNTA(ADEQUAÇÃO!A3:A8952) -> 0.10783328 | D3: =AVERAGE(Tabela1[[#This Row],[Performance Score ]]:'ADEQUAÇÃO'!Q8952) -> 3.3943457 | E3: =AVERAGE(Tabela1[[#This Row],[Tenure]]:'ADEQUAÇÃO'!O8952) -> 6.1369584
